data/depth_sample.csv
snap,ts_ns,side,rank,price,size
0,1784621730147963300,b,0,66240.38,0.03887981
0,1784621730147963300,b,1,66239.05,0.01509684
0,1784621730147963300,b,2,66238.73,0.00683906
0,1784621730147963300,b,3,66237.56,0.001541
0,1784621730147963300,b,4,66237.48,0.0007456
0,1784621730147963300,b,5,66236.8,0.00153174
0,1784621730147963300,b,6,66236.5,0.00660464
0,1784621730147963300,b,7,66236.43,0.03434449
0,1784621730147963300,b,8,66236,0.0079
0,1784621730147963300,b,9,66235.64,0.52015733
0,1784621730147963300,b,10,66234,0.0083
0,1784621730147963300,b,11,66233.6,0.00153174
0,1784621730147963300,a,0,66240.39,1.74598343
0,1784621730147963300,a,1,66241.72,0.01509622
0,1784621730147963300,a,2,66242,0.0079
0,1784621730147963300,a,3,66242.05,0.0056779
0,1784621730147963300,a,4,66242.45,0.0227032
0,1784621730147963300,a,5,66242.46,0.07209876
0,1784621730147963300,a,6,66242.47,0.12076844
0,1784621730147963300,a,7,66243.2,0.00153174
0,1784621730147963300,a,8,66243.4,0.09070899
0,1784621730147963300,a,9,66243.41,0.12364228
0,1784621730147963300,a,10,66244,0.0079
0,1784621730147963300,a,11,66244.28,0.00660473
1,1784621731100776000,b,0,66222.2,0.00155556
1,1784621731100776000,b,1,66221.53,0.00528526
1,1784621731100776000,b,2,66221.5,0.10989397
1,1784621731100776000,b,3,66220.8,0.00153174
1,1784621731100776000,b,4,66220,0.01
1,1784621731100776000,b,5,66219.87,0.00528526
1,1784621731100776000,b,6,66219.79,1.7e-05
1,1784621731100776000,b,7,66218.55,0.62002035
1,1784621731100776000,b,8,66218.5,0.06
1,1784621731100776000,b,9,66217.64,0.00660657
1,1784621731100776000,b,10,66217.6,0.00153174
1,1784621731100776000,b,11,66217.52,0.00044028
1,1784621731100776000,a,0,66223.77,0.03342
1,1784621731100776000,a,1,66223.79,0.05872
1,1784621731100776000,a,2,66227.08,0.0253
1,1784621731100776000,a,3,66227.22,0.11600899
1,1784621731100776000,a,4,66227.8,0.09553241
1,1784621731100776000,a,5,66227.81,0.12900255
1,1784621731100776000,a,6,66228.08,0.0227032
1,1784621731100776000,a,7,66230.16,0.09070899
1,1784621731100776000,a,8,66232.15,0.09070899
1,1784621731100776000,a,9,66233.55,0.12078471
1,1784621731100776000,a,10,66234.13,0.22404106
1,1784621731100776000,a,11,66234.14,0.09070899
2,1784621731271491800,b,0,66229.47,0.03420281
2,1784621731271491800,b,1,66229.46,0.03420281
2,1784621731271491800,b,2,66229.45,0.03420281
2,1784621731271491800,b,3,66223.87,0.00528497
2,1784621731271491800,b,4,66223.21,0.00011868
2,1784621731271491800,b,5,66222.94,5.064e-05
2,1784621731271491800,b,6,66222.21,0.02528497
2,1784621731271491800,b,7,66220.8,0.00153174
2,1784621731271491800,b,8,66220.59,0.00010127
2,1784621731271491800,b,9,66220,0.01
2,1784621731271491800,b,10,66219.79,1.7e-05
2,1784621731271491800,b,11,66219.34,0.00660624
2,1784621731271491800,a,0,66230.16,0.09070899
2,1784621731271491800,a,1,66231.1,0.00660624
2,1784621731271491800,a,2,66231.69,0.00660618
2,1784621731271491800,a,3,66232.15,0.09070899
2,1784621731271491800,a,4,66233.76,0.06281
2,1784621731271491800,a,5,66233.93,0.06281
2,1784621731271491800,a,6,66234.14,0.09070899
2,1784621731271491800,a,7,66235.88,0.0075455
2,1784621731271491800,a,8,66235.89,0.03342
2,1784621731271491800,a,9,66237.73,0.0227032
2,1784621731271491800,a,10,66238,0.09070899
2,1784621731271491800,a,11,66238.01,0.03342
3,1784621731566438400,b,0,66225.42,0.04717729
3,1784621731566438400,b,1,66224.09,0.01510024
3,1784621731566438400,b,2,66223.21,0.00011868
3,1784621731566438400,b,3,66221.5,0.02604761
3,1784621731566438400,b,4,66220.8,0.00153174
3,1784621731566438400,b,5,66220.45,0.00755054
3,1784621731566438400,b,6,66220,0.01
3,1784621731566438400,b,7,66219.79,1.7e-05
3,1784621731566438400,b,8,66219,1
3,1784621731566438400,b,9,66218.8,0.00755073
3,1784621731566438400,b,10,66217.63,0.04540639
3,1784621731566438400,b,11,66217.6,0.00153174
3,1784621731566438400,a,0,66225.43,0.14110988
3,1784621731566438400,a,1,66225.62,0.09070899
3,1784621731566438400,a,2,66226,0.0083
3,1784621731566438400,a,3,66226.19,0.12079814
3,1784621731566438400,a,4,66226.76,0.01509964
3,1784621731566438400,a,5,66227.09,0.00528497
3,1784621731566438400,a,6,66227.67,0.09070899
3,1784621731566438400,a,7,66228,0.0083
3,1784621731566438400,a,8,66229.32,0.00660622
3,1784621731566438400,a,9,66230,0.0083
3,1784621731566438400,a,10,66230.6,0.09070899
3,1784621731566438400,a,11,66231.99,0.02
4,1784621732497011000,b,0,66225.42,0.08151309
4,1784621732497011000,b,1,66224.09,0.01510024
4,1784621732497011000,b,2,66223.21,0.00011868
4,1784621732497011000,b,3,66221.5,0.02604761
4,1784621732497011000,b,4,66220.8,0.00153174
4,1784621732497011000,b,5,66220.45,0.00755054
4,1784621732497011000,b,6,66220,0.01
4,1784621732497011000,b,7,66219.8,0.02
4,1784621732497011000,b,8,66219.79,1.7e-05
4,1784621732497011000,b,9,66219.01,0.02
4,1784621732497011000,b,10,66219,1
4,1784621732497011000,b,11,66218.8,0.01510146
4,1784621732497011000,a,0,66225.43,0.18280683
4,1784621732497011000,a,1,66225.61,0.20917127
4,1784621732497011000,a,2,66225.62,0.09070899
4,1784621732497011000,a,3,66225.63,0.001641
4,1784621732497011000,a,4,66226,0.0083
4,1784621732497011000,a,5,66226.19,0.12079814
4,1784621732497011000,a,6,66226.76,0.01509964
4,1784621732497011000,a,7,66227.09,0.00528497
4,1784621732497011000,a,8,66227.67,0.09070899
4,1784621732497011000,a,9,66228,0.0083
4,1784621732497011000,a,10,66228.32,0.00292268
4,1784621732497011000,a,11,66229.32,0.00660622
5,1784621733356898100,b,0,66223.21,0.03422149
5,1784621733356898100,b,1,66221.58,0.01339307
5,1784621733356898100,b,2,66221.5,0.02604761
5,1784621733356898100,b,3,66220.8,0.00153174
5,1784621733356898100,b,4,66220.45,0.00755054
5,1784621733356898100,b,5,66220,0.01
5,1784621733356898100,b,6,66219.79,1.7e-05
5,1784621733356898100,b,7,66217.6,0.00153174
5,1784621733356898100,b,8,66216.08,1.637e-05
5,1784621733356898100,b,9,66215.69,0.04540639
5,1784621733356898100,b,10,66215,0.01
5,1784621733356898100,b,11,66214.4,0.00153174
5,1784621733356898100,a,0,66225.43,0.10967851
5,1784621733356898100,a,1,66225.61,0.09590963
5,1784621733356898100,a,2,66226,0.0083
5,1784621733356898100,a,3,66226.19,0.12079814
5,1784621733356898100,a,4,66226.76,0.01509964
5,1784621733356898100,a,5,66227.09,0.00528497
5,1784621733356898100,a,6,66227.48,0.06305228
5,1784621733356898100,a,7,66227.49,0.09070899
5,1784621733356898100,a,8,66228,0.0083
5,1784621733356898100,a,9,66229.32,0.00660622
5,1784621733356898100,a,10,66230,0.0083
5,1784621733356898100,a,11,66230.59,0.07029585
6,1784621734186337400,b,0,66221.58,0.04749565
6,1784621734186337400,b,1,66221.5,0.02604761
6,1784621734186337400,b,2,66220.8,0.00153174
6,1784621734186337400,b,3,66220.25,0.01510112
6,1784621734186337400,b,4,66220,0.01
6,1784621734186337400,b,5,66219.79,1.7e-05
6,1784621734186337400,b,6,66219,1
6,1784621734186337400,b,7,66217.6,0.00153174
6,1784621734186337400,b,8,66216.61,0.01510196
6,1784621734186337400,b,9,66216.08,1.637e-05
6,1784621734186337400,b,10,66215.69,0.04540639
6,1784621734186337400,b,11,66215,0.01
6,1784621734186337400,a,0,66221.59,0.2697286
6,1784621734186337400,a,1,66222.92,0.01510052
6,1784621734186337400,a,2,66223.22,0.16995862
6,1784621734186337400,a,3,66223.25,0.00528528
6,1784621734186337400,a,4,66223.71,0.001633
6,1784621734186337400,a,5,66224,0.0083
6,1784621734186337400,a,6,66224.1,0.09070899
6,1784621734186337400,a,7,66225.43,0.06721261
6,1784621734186337400,a,8,66225.47,0.00292273
6,1784621734186337400,a,9,66225.48,0.0066066
6,1784621734186337400,a,10,66226,0.0083
6,1784621734186337400,a,11,66227.48,0.06305228
7,1784621735826241600,b,0,66221.58,0.10094092
7,1784621735826241600,b,1,66221.5,0.02604761
7,1784621735826241600,b,2,66220.8,0.00153174
7,1784621735826241600,b,3,66220.25,0.01510112
7,1784621735826241600,b,4,66220,0.01
7,1784621735826241600,b,5,66219.79,1.7e-05
7,1784621735826241600,b,6,66219,1
7,1784621735826241600,b,7,66217.6,0.00153174
7,1784621735826241600,b,8,66216.61,0.01510196
7,1784621735826241600,b,9,66216.08,1.637e-05
7,1784621735826241600,b,10,66215.69,0.04540639
7,1784621735826241600,b,11,66215,0.01
7,1784621735826241600,a,0,66221.59,0.32656206
